Workbook

Sheet Calculator
B1: CVSS v3.1 Modified / Environmental Score Calculator
B2: Turns a published base CVE vector into the real threat score for YOUR environment. Edit the yellow cells; everything else recalculates automatically.
B4: HOW TO USE: pick a value in each yellow drop-down. Leave 'Not Defined' to keep the published base value.
B6: ① BASE METRICS (the published vulnerability vector, e.g. from NVD) | H6: RESULTS
B7: Metric | C7: Your selection | E7: Weight | F7: Code | H7: Base Score (CVSS-B) | I7: =C46 -> 9.8
B8: Attack Vector (AV) | C8: Network | E8: =VLOOKUP(C8,Reference!$A$6:$C$9,3,FALSE()) -> 0.85 | F8: =VLOOKUP(C8,Reference!$A$6:$C$9,2,FALSE()) -> N | H8: Base severity | I8: =IF(C46=0,"None",IF(C46<4,"Low",IF(C46<7,"Medium",IF(C46<9,"High","Critical")))) -> Critical
B9: Attack Complexity (AC) | C9: Low | E9: =VLOOKUP(C9,Reference!$A$13:$C$14,3,FALSE()) -> 0.77 | F9: =VLOOKUP(C9,Reference!$A$13:$C$14,2,FALSE()) -> L
B10: Privileges Required (PR) | C10: None | E10: =VLOOKUP(C10,Reference!$A$18:$D$20,IF(C12="Changed",4,3),FALSE()) -> 0.85 | F10: =VLOOKUP(C10,Reference!$A$18:$D$20,2,FALSE()) -> N | H10: REAL THREAT SCORE (Environmental, CVSS-BE/BTE) | I10: =C52 -> 9.8
B11: User Interaction (UI) | C11: None | E11: =VLOOKUP(C11,Reference!$A$24:$C$25,3,FALSE()) -> 0.85 | F11: =VLOOKUP(C11,Reference!$A$24:$C$25,2,FALSE()) -> N | H11: Threat severity | I11: =IF(C52=0,"None",IF(C52<4,"Low",IF(C52<7,"Medium",IF(C52<9,"High","Critical")))) -> Critical
B12: Scope (S) | C12: Unchanged | F12: =VLOOKUP(C12,Reference!$A$29:$C$30,2,FALSE()) -> U
B13: Confidentiality (C) | C13: High | E13: =VLOOKUP(C13,Reference!$A$34:$C$36,3,FALSE()) -> 0.56 | F13: =VLOOKUP(C13,Reference!$A$34:$C$36,2,FALSE()) -> H | H13: CVSS vector string (paste into the official FIRST calculator to verify):
B14: Integrity (I) | C14: High | E14: =VLOOKUP(C14,Reference!$A$34:$C$36,3,FALSE()) -> 0.56 | F14: =VLOOKUP(C14,Reference!$A$34:$C$36,2,FALSE()) -> H | H14: ="CVSS:3.1/AV:"&F8&"/AC:"&F9&"/PR:"&F10&"/UI:"&F11&"/S:"&F12&"/C:"&F13&"/I:"&F14&"/A:"&F15&IF(C36="Not Defined","","/E:"&VLOOKUP(C36,Reference!$A$40:$C$44,2,FALSE()))&IF(C37="Not Defined","","/RL:"&VLOOKUP(C37,Reference!$A$48:$C$52,2,FALSE()))&IF(C38="Not Defined","","/RC:"&VLOOKUP(C38,Reference!$A$56:$C$59,2,FALSE()))&IF(C30="Not Defined","","/CR:"&VLOOKUP(C30,Reference!$A$63:$C$66,2,FALSE()))&IF(C31="Not Defined","","/IR:"&VLOOKUP(C31,Reference!$A$63:$C$66,2,FALSE()))&IF(C32="Not Defined","","/AR:"&VLOOKUP(C32,Reference!$A$63:$C$66,2,FALSE()))&IF(C19="Not Defined","","/MAV:"&VLOOKUP(C19,Reference!$A$6:$C$9,2,FALSE()))&IF(C20="Not Defined","","/MAC:"&VLOOKUP(C20,Reference!$A$13:$C$14,2,FALSE()))&IF(C21="Not Defined","","/MPR:"&VLOOKUP(C21,Reference!$A$18:$D$20,2,FALSE()))&IF(C22="Not Defined","","/MUI:"&VLOOKUP(C22,Reference!$A$24:$C$25,2,FALSE()))&IF(C23="Not Defined","","/MS:"&VLOOKUP(C23,Reference!$A$29:$C$30,2,FALSE()))&IF(C24="Not Defined","","/MC:"&VLOOKUP(C24,Reference!$A$34:$C$36,2,FALSE()))&IF(C25="Not Defined","","/MI:"&VLOOKUP(C25,Reference!$A$34:$C$36,2,FALSE()))&IF(C26="Not Defined","","/MA:"&VLOOKUP(C26,Reference!$A$34:$C$36,2,FALSE())) -> CVSS:3.1/AV:N/AC:L/PR:N/UI:N/S:U/C:H/I:H/A:H
B15: Availability (A) | C15: High | E15: =VLOOKUP(C15,Reference!$A$34:$C$36,3,FALSE()) -> 0.56 | F15: =VLOOKUP(C15,Reference!$A$34:$C$36,2,FALSE()) -> H
B17: ② MODIFIED BASE METRICS (override the base for YOUR environment)
B18: Metric | C18: Your selection | D18: Effective | E18: Weight | F18: Code
B19: Modified Attack Vector (MAV) | C19: Not Defined | D19: =IF(C19="Not Defined",C8,C19) -> Network | E19: =VLOOKUP(D19,Reference!$A$6:$C$9,3,FALSE()) -> 0.85 | F19: =VLOOKUP(D19,Reference!$A$6:$C$9,2,FALSE()) -> N
B20: Modified Attack Complexity (MAC) | C20: Not Defined | D20: =IF(C20="Not Defined",C9,C20) -> Low | E20: =VLOOKUP(D20,Reference!$A$13:$C$14,3,FALSE()) -> 0.77 | F20: =VLOOKUP(D20,Reference!$A$13:$C$14,2,FALSE()) -> L
B21: Modified Privileges Required (MPR) | C21: Not Defined | D21: =IF(C21="Not Defined",C10,C21) -> None | E21: =VLOOKUP(D21,Reference!$A$18:$D$20,IF(D23="Changed",4,3),FALSE()) -> 0.85 | F21: =VLOOKUP(D21,Reference!$A$18:$D$20,2,FALSE()) -> N
B22: Modified User Interaction (MUI) | C22: Not Defined | D22: =IF(C22="Not Defined",C11,C22) -> None | E22: =VLOOKUP(D22,Reference!$A$24:$C$25,3,FALSE()) -> 0.85 | F22: =VLOOKUP(D22,Reference!$A$24:$C$25,2,FALSE()) -> N
B23: Modified Scope (MS) | C23: Not Defined | D23: =IF(C23="Not Defined",C12,C23) -> Unchanged | F23: =VLOOKUP(D23,Reference!$A$29:$C$30,2,FALSE()) -> U
B24: Modified Confidentiality (MC) | C24: Not Defined | D24: =IF(C24="Not Defined",C13,C24) -> High | E24: =VLOOKUP(D24,Reference!$A$34:$C$36,3,FALSE()) -> 0.56 | F24: =VLOOKUP(D24,Reference!$A$34:$C$36,2,FALSE()) -> H
B25: Modified Integrity (MI) | C25: Not Defined | D25: =IF(C25="Not Defined",C14,C25) -> High | E25: =VLOOKUP(D25,Reference!$A$34:$C$36,3,FALSE()) -> 0.56 | F25: =VLOOKUP(D25,Reference!$A$34:$C$36,2,FALSE()) -> H
B26: Modified Availability (MA) | C26: Not Defined | D26: =IF(C26="Not Defined",C15,C26) -> High | E26: =VLOOKUP(D26,Reference!$A$34:$C$36,3,FALSE()) -> 0.56 | F26: =VLOOKUP(D26,Reference!$A$34:$C$36,2,FALSE()) -> H
B28: ③ SECURITY REQUIREMENTS (how critical C / I / A are to your business)
B29: Metric | C29: Your selection | E29: Weight | F29: Code
B30: Confidentiality Requirement (CR) | C30: Not Defined | E30: =VLOOKUP(C30,Reference!$A$63:$C$66,3,FALSE()) -> 1 | F30: =VLOOKUP(C30,Reference!$A$63:$C$66,2,FALSE()) -> X
B31: Integrity Requirement (IR) | C31: Not Defined | E31: =VLOOKUP(C31,Reference!$A$63:$C$66,3,FALSE()) -> 1 | F31: =VLOOKUP(C31,Reference!$A$63:$C$66,2,FALSE()) -> X
B32: Availability Requirement (AR) | C32: Not Defined | E32: =VLOOKUP(C32,Reference!$A$63:$C$66,3,FALSE()) -> 1 | F32: =VLOOKUP(C32,Reference!$A$63:$C$66,2,FALSE()) -> X
B34: ④ THREAT (TEMPORAL) METRICS (current real-world exploit status — optional)
B35: Metric | C35: Your selection | E35: Weight | F35: Code
B36: Exploit Code Maturity (E) | C36: Not Defined | E36: =VLOOKUP(C36,Reference!$A$40:$C$44,3,FALSE()) -> 1 | F36: =VLOOKUP(C36,Reference!$A$40:$C$44,2,FALSE()) -> X
B37: Remediation Level (RL) | C37: Not Defined | E37: =VLOOKUP(C37,Reference!$A$48:$C$52,3,FALSE()) -> 1 | F37: =VLOOKUP(C37,Reference!$A$48:$C$52,2,FALSE()) -> X
B38: Report Confidence (RC) | C38: Not Defined | E38: =VLOOKUP(C38,Reference!$A$56:$C$59,3,FALSE()) -> 1 | F38: =VLOOKUP(C38,Reference!$A$56:$C$59,2,FALSE()) -> X
B41: CALCULATION STEPS (live — these are the exact CVSS v3.1 equations)
B42: Step | C42: Value | D42: What it computes
B43: ISS (Impact Sub-Score) | C43: =1-((1-E13)*(1-E14)*(1-E15)) -> 0.914816 | D43: 1 − [(1−C)(1−I)(1−A)]
B44: Exploitability (Base) | C44: =8.22*E8*E9*E10*E11 -> 3.8870428 | D44: 8.22 × AV × AC × PR × UI
B45: Impact (Base) | C45: =IF(C12="Unchanged",6.42*C43,7.52*(C43-0.029)-3.25*(C43-0.02)^15) -> 5.8731187 | D45: Unchanged: 6.42 × ISS Changed: 7.52 × (ISS−0.029) − 3.25 × (ISS−0.02)¹⁵
B46: BASE SCORE (CVSS-B) | C46: =IF(C45<=0,0,IF(MOD(ROUND((MIN(IF(C12="Changed",1.08,1)*(C45+C44),10))*100000,0),10000)=0,ROUND((MIN(IF(C12="Changed",1.08,1)*(C45+C44),10))*100000,0)/100000,(INT(ROUND((MIN(IF(C12="Changed",1.08,1)*(C45+C44),10))*100000,0)/10000)+1)/10)) -> 9.8 | D46: 0 if Impact ≤ 0, else Roundup( min( [1.08 if Scope Changed] × (Impact + Exploitability), 10) )
B48: MISS (Modified Impact Sub-Score) | C48: =MIN(1-((1-E30*E24)*(1-E31*E25)*(1-E32*E26)),0.915) -> 0.914816 | D48: min( 1 − [(1−CR×MC)(1−IR×MI)(1−AR×MA)] , 0.915 )
...

Sheet Reference
A1: CVSS v3.1 Metric Constants — source: FIRST.org Specification, Table 16
A2: These are the official numeric weights the formulas look up. Do not edit unless the standard changes.
A4: Attack Vector (AV / MAV)
A5: Value | B5: Code | C5: Weight
A6: Network | B6: N | C6: 0.85
A7: Adjacent | B7: A | C7: 0.62
A8: Local | B8: L | C8: 0.55
A9: Physical | B9: P | C9: 0.2
A11: Attack Complexity (AC / MAC)
A12: Value | B12: Code | C12: Weight
A13: Low | B13: L | C13: 0.77
A14: High | B14: H | C14: 0.44
A16: Privileges Required (PR / MPR)
A17: Value | B17: Code | C17: Weight (Scope Unchanged) | D17: Weight (Scope Changed)
A18: None | B18: N | C18: 0.85 | D18: 0.85
A19: Low | B19: L | C19: 0.62 | D19: 0.68
A20: High | B20: H | C20: 0.27 | D20: 0.5
A22: User Interaction (UI / MUI)
A23: Value | B23: Code | C23: Weight
A24: None | B24: N | C24: 0.85
A25: Required | B25: R | C25: 0.62
A27: Scope (S / MS)
A28: Value | B28: Code | C28: Weight
A29: Unchanged | B29: U | C29: 0
A30: Changed | B30: C | C30: 0
A32: Confidentiality / Integrity / Availability (C,I,A & MC,MI,MA)
A33: Value | B33: Code | C33: Weight
A34: High | B34: H | C34: 0.56
A35: Low | B35: L | C35: 0.22
A36: None | B36: N | C36: 0
A38: Exploit Code Maturity (E)
A39: Value | B39: Code | C39: Weight
A40: Not Defined | B40: X | C40: 1
A41: High | B41: H | C41: 1
A42: Functional | B42: F | C42: 0.97
A43: Proof-of-Concept | B43: P | C43: 0.94
A44: Unproven | B44: U | C44: 0.91
A46: Remediation Level (RL)
A47: Value | B47: Code | C47: Weight
A48: Not Defined | B48: X | C48: 1
...

Sheet How it works
B1: How this calculator works
B3: What problem this solves
B4: A published CVE comes with a BASE score (CVSS-B). The base score deliberately assumes a reasonable worst-case and ignores your environment. The same vulnerability can be far more - or far less - dangerous to you depending on where the asset sits, what controls you have, how critical the data is, and whether an exploit actually exists in the wild. CVSS lets you refine the base into an ENVIRONMENTAL score (optionally also adjusted by THREAT / Temporal metrics). That refined number is your 'real threat score'.
B5: You provide the base vector and your modifications on the Calculator tab. The sheet looks up the official numeric weight for every choice (Reference tab) and runs the exact CVSS v3.1 equations shown below.
B6: Which CVSS version this uses, and why
B7: This calculator implements CVSS v3.1 - the version used for the large majority of CVEs in the NVD and the one with a clean, closed-form formula a spreadsheet can reproduce exactly. CVSS v4.0 (released Nov 2023) is the newest standard, but it does NOT use an algebraic environmental formula: it scores via a large lookup table of 'MacroVectors' plus an interpolation routine, which cannot be expressed as a few transparent cell formulas. If you specifically need a v4.0 number, use the official FIRST v4.0 calculator. The concept - base, then modify for your environment and threat reality - is identical across both versions.
B8: Step 1 - Base Score (intrinsic severity)
B9: ISS = 1 - [ (1-C) x (1-I) x (1-A) ]
B10: Exploitability = 8.22 x AV x AC x PR x UI
B11: Impact = 6.42 x ISS (if Scope = Unchanged)
B12: Impact = 7.52 x (ISS-0.029) - 3.25 x (ISS-0.02)^15 (if Scope = Changed)
B13: BaseScore = 0 if Impact<=0, else Roundup( min( f x (Impact+Exploitability), 10) )
... B32: - Source of every constant and formula: FIRST.org, CVSS v3.1 Specification Document, Sections 7.3-7.4 and Appendix A (https://www.first.org/cvss/v3-1/specification-document).
